Workbook

Sheet README
A1: Deforestation attributed to cropland, pasture and forest-plantation expansion, by EPPA region (AFRC aggregation)
A3: Source: DeDuCE v2.1 - Singh, C., Persson, U. M., Croft, S., Kastner, T. & West, C. D. (2024). Commodity-driven deforestation, associated carbon emissions and trade 2001-2023 (Version 2.1) [Dataset]. Zenodo. https://doi.org/10.5281/zenodo.10633818
A4: Method: Singh, C. & Persson, U. M. (2026). Global patterns of commodity-driven deforestation and associated carbon emissions. Nature Food 7, 138-151. https://doi.org/10.1038/s43016-026-01305-4
A5: File used: 'DeDuCE_Deforestation attributed to agricultural and forestry commodities (2001-2023).xlsx', column 'Deforestation attribution, unamortized (ha)':
A6: the forest loss of each year (Hansen/GFC loss, DeDuCE's forest definition) attributed to the land use that replaced it. Gross loss, no regrowth netted out.
A7: Not the 5-year amortized 'deforestation risk' column, which spreads each year's loss over the following five years of production.
A9: Categories (sheet country_annual_ha, column category):
A10: crop = all DeDuCE crop groups (cereals, oilseeds, fruit and nuts, vegetables, roots and tubers, pulses, stimulant and spice crops, fibre crops, sugar crops)
A11: live = DeDuCE group 'Pasture' (cattle meat and leather)
A12: fors = DeDuCE group 'Forest plantation'
A14: Regions: the 28 EPPA regions of eppa_afrc_regions_countries.csv. Countries with their own GTAP code are assigned directly; the 46 DeDuCE countries without one
A15: go to the EPPA region holding their GTAP residual region (sheet country_mapping, column basis). Two DeDuCE composites: 'SRB and MNE' (2001-2005) -> ROE;
... A24: Built 2026-10-06 from the Zenodo file downloaded 2026-09-18 (folder zenodo_v2.1), script build_eppa_defor.py.

Sheet periods
A1: period | B1: first year | C1: last year | D1: years
A2: 2007-2010 | B2: 2008 | C2: 2010 | D2: =C2-B2+1 -> 3
A3: 2010-2015 | B3: 2011 | C3: 2015 | D3: =C3-B3+1 -> 5
A4: 2015-2020 | B4: 2016 | C4: 2020 | D4: =C4-B4+1 -> 5
A5: 2020-2023 | B5: 2021 | C5: 2023 | D5: =C5-B5+1 -> 3
A7: Blue cells are inputs: 'A-B' = years A+1 to B. Edit first/last year and the rate and cumulative sheets recompute.

Sheet rates_ha_per_yr
A1: EPPA region | B1: region name | C1: ="crop "&periods!$A$2 -> crop 2007-2010 | D1: ="crop "&periods!$A$3 -> crop 2010-2015 | E1: ="crop "&periods!$A$4 -> crop 2015-2020 | F1: ="crop "&periods!$A$5 -> crop 2020-2023 | G1: ="live "&periods!$A$2 -> live 2007-2010 | H1: ="live "&periods!$A$3 -> live 2010-2015 | I1: ="live "&periods!$A$4 -> live 2015-2020 | J1: ="live "&periods!$A$5 -> live 2020-2023 | K1: ="fors "&periods!$A$2 -> fors 2007-2010 | L1: ="fors "&periods!$A$3 -> fors 2010-2015 | M1: ="fors "&periods!$A$4 -> fors 2015-2020 | N1: ="fors "&periods!$A$5 -> fors 2020-2023 | O1: ="total "&periods!$A$2 -> total 2007-2010 | P1: ="total "&periods!$A$3 -> total 2010-2015 | Q1: ="total "&periods!$A$4 -> total 2015-2020 | R1: ="total "&periods!$A$5 -> total 2020-2023
A2: hectares per year, average over the period's years
A3: USA | B3: United States of America | C3: =SUMPRODUCT((region_annual_ha!$A$2:$A$85=$A3)*(region_annual_ha!$B$2:$B$85="crop")*(region_annual_ha!$D$1:$Z$1>=periods!$B$2)*(region_annual_ha!$D$1:$Z$1<=periods!$C$2)*region_annual_ha!$D$2:$Z$85)/(periods!$C$2-periods!$B$2+1) -> 17635.589 | D3: =SUMPRODUCT((region_annual_ha!$A$2:$A$85=$A3)*(region_annual_ha!$B$2:$B$85="crop")*(region_annual_ha!$D$1:$Z$1>=periods!$B$3)*(region_annual_ha!$D$1:$Z$1<=periods!$C$3)*region_annual_ha!$D$2:$Z$85)/(periods!$C$3-periods!$B$3+1) -> 48593.917 | E3: =SUMPRODUCT((region_annual_ha!$A$2:$A$85=$A3)*(region_annual_ha!$B$2:$B$85="crop")*(region_annual_ha!$D$1:$Z$1>=periods!$B$4)*(region_annual_ha!$D$1:$Z$1<=periods!$C$4)*region_annual_ha!$D$2:$Z$85)/(periods!$C$4-periods!$B$4+1) -> 22616.094 | F3: =SUMPRODUCT((region_annual_ha!$A$2:$A$85=$A3)*(region_annual_ha!$B$2:$B$85="crop")*(region_annual_ha!$D$1:$Z$1>=periods!$B$5)*(region_annual_ha!$D$1:$Z$1<=periods!$C$5)*region_annual_ha!$D$2:$Z$85)/(periods!$C$5-periods!$B$5+1) -> 6667.1677 | G3: =SUMPRODUCT((region_annual_ha!$A$2:$A$85=$A3)*(region_annual_ha!$B$2:$B$85="live")*(region_annual_ha!$D$1:$Z$1>=periods!$B$2)*(region_annual_ha!$D$1:$Z$1<=periods!$C$2)*region_annual_ha!$D$2:$Z$85)/(periods!$C$2-periods!$B$2+1) -> 75655.572 | H3: =SUMPRODUCT((region_annual_ha!$A$2:$A$85=$A3)*(region_annual_ha!$B$2:$B$85="live")*(region_annual_ha!$D$1:$Z$1>=periods!$B$3)*(region_annual_ha!$D$1:$Z$1<=periods!$C$3)*region_annual_ha!$D$2:$Z$85)/(periods!$C$3-periods!$B$3+1) -> 46036.876 | I3: =SUMPRODUCT((region_annual_ha!$A$2:$A$85=$A3)*(region_annual_ha!$B$2:$B$85="live")*(region_annual_ha!$D$1:$Z$1>=periods!$B$4)*(region_annual_ha!$D$1:$Z$1<=periods!$C$4)*region_annual_ha!$D$2:$Z$85)/(periods!$C$4-periods!$B$4+1) -> 61863.139 | J3: =SUMPRODUCT((region_annual_ha!$A$2:$A$85=$A3)*(region_annual_ha!$B$2:$B$85="live")*(region_annual_ha!$D$1:$Z$1>=periods!$B$5)*(region_annual_ha!$D$1:$Z$1<=periods!$C$5)*region_annual_ha!$D$2:$Z$85)/(periods!$C$5-periods!$B$5+1) -> 39455.918 | K3: =SUMPRODUCT((region_annual_ha!$A$2:$A$85=$A3)*(region_annual_ha!$B$2:$B$85="fors")*(region_annual_ha!$D$1:$Z$1>=periods!$B$2)*(region_annual_ha!$D$1:$Z$1<=periods!$C$2)*region_annual_ha!$D$2:$Z$85)/(periods!$C$2-periods!$B$2+1) -> 201700 | L3: =SUMPRODUCT((region_annual_ha!$A$2:$A$85=$A3)*(region_annual_ha!$B$2:$B$85="fors")*(region_annual_ha!$D$1:$Z$1>=periods!$B$3)*(region_annual_ha!$D$1:$Z$1<=periods!$C$3)*region_annual_ha!$D$2:$Z$85)/(periods!$C$3-periods!$B$3+1) -> 183160 | M3: =SUMPRODUCT((region_annual_ha!$A$2:$A$85=$A3)*(region_annual_ha!$B$2:$B$85="fors")*(region_annual_ha!$D$1:$Z$1>=periods!$B$4)*(region_annual_ha!$D$1:$Z$1<=periods!$C$4)*region_annual_ha!$D$2:$Z$85)/(periods!$C$4-periods!$B$4+1) -> 59000 | N3: =SUMPRODUCT((region_annual_ha!$A$2:$A$85=$A3)*(region_annual_ha!$B$2:$B$85="fors")*(region_annual_ha!$D$1:$Z$1>=periods!$B$5)*(region_annual_ha!$D$1:$Z$1<=periods!$C$5)*region_annual_ha!$D$2:$Z$85)/(periods!$C$5-periods!$B$5+1) -> 0 | O3: =C3+G3+K3 -> 294991.16 | P3: =D3+H3+L3 -> 277790.79 | Q3: =E3+I3+M3 -> 143479.23 | R3: =F3+J3+N3 -> 46123.086
A4: CAN | B4: Canada | C4: =SUMPRODUCT((region_annual_ha!$A$2:$A$85=$A4)*(region_annual_ha!$B$2:$B$85="crop")*(region_annual_ha!$D$1:$Z$1>=periods!$B$2)*(region_annual_ha!$D$1:$Z$1<=periods!$C$2)*region_annual_ha!$D$2:$Z$85)/(periods!$C$2-periods!$B$2+1) -> 9062.0926 | D4: =SUMPRODUCT((region_annual_ha!$A$2:$A$85=$A4)*(region_annual_ha!$B$2:$B$85="crop")*(region_annual_ha!$D$1:$Z$1>=periods!$B$3)*(region_annual_ha!$D$1:$Z$1<=periods!$C$3)*region_annual_ha!$D$2:$Z$85)/(periods!$C$3-periods!$B$3+1) -> 22836.703 | E4: =SUMPRODUCT((region_annual_ha!$A$2:$A$85=$A4)*(region_annual_ha!$B$2:$B$85="crop")*(region_annual_ha!$D$1:$Z$1>=periods!$B$4)*(region_annual_ha!$D$1:$Z$1<=periods!$C$4)*region_annual_ha!$D$2:$Z$85)/(periods!$C$4-periods!$B$4+1) -> 7173.4741 | F4: =SUMPRODUCT((region_annual_ha!$A$2:$A$85=$A4)*(region_annual_ha!$B$2:$B$85="crop")*(region_annual_ha!$D$1:$Z$1>=periods!$B$5)*(region_annual_ha!$D$1:$Z$1<=periods!$C$5)*region_annual_ha!$D$2:$Z$85)/(periods!$C$5-periods!$B$5+1) -> 0 | G4: =SUMPRODUCT((region_annual_ha!$A$2:$A$85=$A4)*(region_annual_ha!$B$2:$B$85="live")*(region_annual_ha!$D$1:$Z$1>=periods!$B$2)*(region_annual_ha!$D$1:$Z$1<=periods!$C$2)*region_annual_ha!$D$2:$Z$85)/(periods!$C$2-periods!$B$2+1) -> 3382.6761 | H4: =SUMPRODUCT((region_annual_ha!$A$2:$A$85=$A4)*(region_annual_ha!$B$2:$B$85="live")*(region_annual_ha!$D$1:$Z$1>=periods!$B$3)*(region_annual_ha!$D$1:$Z$1<=periods!$C$3)*region_annual_ha!$D$2:$Z$85)/(periods!$C$3-periods!$B$3+1) -> 0 | I4: =SUMPRODUCT((region_annual_ha!$A$2:$A$85=$A4)*(region_annual_ha!$B$2:$B$85="live")*(region_annual_ha!$D$1:$Z$1>=periods!$B$4)*(region_annual_ha!$D$1:$Z$1<=periods!$C$4)*region_annual_ha!$D$2:$Z$85)/(periods!$C$4-periods!$B$4+1) -> 6266.9733 | J4: =SUMPRODUCT((region_annual_ha!$A$2:$A$85=$A4)*(region_annual_ha!$B$2:$B$85="live")*(region_annual_ha!$D$1:$Z$1>=periods!$B$5)*(region_annual_ha!$D$1:$Z$1<=periods!$C$5)*region_annual_ha!$D$2:$Z$85)/(periods!$C$5-periods!$B$5+1) -> 5417.053 | K4: =SUMPRODUCT((region_annual_ha!$A$2:$A$85=$A4)*(region_annual_ha!$B$2:$B$85="fors")*(region_annual_ha!$D$1:$Z$1>=periods!$B$2)*(region_annual_ha!$D$1:$Z$1<=periods!$C$2)*region_annual_ha!$D$2:$Z$85)/(periods!$C$2-periods!$B$2+1) -> 0 | L4: =SUMPRODUCT((region_annual_ha!$A$2:$A$85=$A4)*(region_annual_ha!$B$2:$B$85="fors")*(region_annual_ha!$D$1:$Z$1>=periods!$B$3)*(region_annual_ha!$D$1:$Z$1<=periods!$C$3)*region_annual_ha!$D$2:$Z$85)/(periods!$C$3-periods!$B$3+1) -> 0 | M4: =SUMPRODUCT((region_annual_ha!$A$2:$A$85=$A4)*(region_annual_ha!$B$2:$B$85="fors")*(region_annual_ha!$D$1:$Z$1>=periods!$B$4)*(region_annual_ha!$D$1:$Z$1<=periods!$C$4)*region_annual_ha!$D$2:$Z$85)/(periods!$C$4-periods!$B$4+1) -> 0 | N4: =SUMPRODUCT((region_annual_ha!$A$2:$A$85=$A4)*(region_annual_ha!$B$2:$B$85="fors")*(region_annual_ha!$D$1:$Z$1>=periods!$B$5)*(region_annual_ha!$D$1:$Z$1<=periods!$C$5)*region_annual_ha!$D$2:$Z$85)/(periods!$C$5-periods!$B$5+1) -> 0 | O4: =C4+G4+K4 -> 12444.769 | P4: =D4+H4+L4 -> 22836.703 | Q4: =E4+I4+M4 -> 13440.447 | R4: =F4+J4+N4 -> 5417.053
A5: MEX | B5: Mexico | C5: =SUMPRODUCT((region_annual_ha!$A$2:$A$85=$A5)*(region_annual_ha!$B$2:$B$85="crop")*(region_annual_ha!$D$1:$Z$1>=periods!$B$2)*(region_annual_ha!$D$1:$Z$1<=periods!$C$2)*region_annual_ha!$D$2:$Z$85)/(periods!$C$2-periods!$B$2+1) -> 7991.3682 | D5: =SUMPRODUCT((region_annual_ha!$A$2:$A$85=$A5)*(region_annual_ha!$B$2:$B$85="crop")*(region_annual_ha!$D$1:$Z$1>=periods!$B$3)*(region_annual_ha!$D$1:$Z$1<=periods!$C$3)*region_annual_ha!$D$2:$Z$85)/(periods!$C$3-periods!$B$3+1) -> 7144.4063 | E5: =SUMPRODUCT((region_annual_ha!$A$2:$A$85=$A5)*(region_annual_ha!$B$2:$B$85="crop")*(region_annual_ha!$D$1:$Z$1>=periods!$B$4)*(region_annual_ha!$D$1:$Z$1<=periods!$C$4)*region_annual_ha!$D$2:$Z$85)/(periods!$C$4-periods!$B$4+1) -> 120927.57 | F5: =SUMPRODUCT((region_annual_ha!$A$2:$A$85=$A5)*(region_annual_ha!$B$2:$B$85="crop")*(region_annual_ha!$D$1:$Z$1>=periods!$B$5)*(region_annual_ha!$D$1:$Z$1<=periods!$C$5)*region_annual_ha!$D$2:$Z$85)/(periods!$C$5-periods!$B$5+1) -> 0 | G5: =SUMPRODUCT((region_annual_ha!$A$2:$A$85=$A5)*(region_annual_ha!$B$2:$B$85="live")*(region_annual_ha!$D$1:$Z$1>=periods!$B$2)*(region_annual_ha!$D$1:$Z$1<=periods!$C$2)*region_annual_ha!$D$2:$Z$85)/(periods!$C$2-periods!$B$2+1) -> 0 | H5: =SUMPRODUCT((region_annual_ha!$A$2:$A$85=$A5)*(region_annual_ha!$B$2:$B$85="live")*(region_annual_ha!$D$1:$Z$1>=periods!$B$3)*(region_annual_ha!$D$1:$Z$1<=periods!$C$3)*region_annual_ha!$D$2:$Z$85)/(periods!$C$3-periods!$B$3+1) -> 22618.827 | I5: =SUMPRODUCT((region_annual_ha!$A$2:$A$85=$A5)*(region_annual_ha!$B$2:$B$85="live")*(region_annual_ha!$D$1:$Z$1>=periods!$B$4)*(region_annual_ha!$D$1:$Z$1<=periods!$C$4)*region_annual_ha!$D$2:$Z$85)/(periods!$C$4-periods!$B$4+1) -> 30007.771 | J5: =SUMPRODUCT((region_annual_ha!$A$2:$A$85=$A5)*(region_annual_ha!$B$2:$B$85="live")*(region_annual_ha!$D$1:$Z$1>=periods!$B$5)*(region_annual_ha!$D$1:$Z$1<=periods!$C$5)*region_annual_ha!$D$2:$Z$85)/(periods!$C$5-periods!$B$5+1) -> 43722.193 | K5: =SUMPRODUCT((region_annual_ha!$A$2:$A$85=$A5)*(region_annual_ha!$B$2:$B$85="fors")*(region_annual_ha!$D$1:$Z$1>=periods!$B$2)*(region_annual_ha!$D$1:$Z$1<=periods!$C$2)*region_annual_ha!$D$2:$Z$85)/(periods!$C$2-periods!$B$2+1) -> 2587.137 | L5: =SUMPRODUCT((region_annual_ha!$A$2:$A$85=$A5)*(region_annual_ha!$B$2:$B$85="fors")*(region_annual_ha!$D$1:$Z$1>=periods!$B$3)*(region_annual_ha!$D$1:$Z$1<=periods!$C$3)*region_annual_ha!$D$2:$Z$85)/(periods!$C$3-periods!$B$3+1) -> 1577.0362 | M5: =SUMPRODUCT((region_annual_ha!$A$2:$A$85=$A5)*(region_annual_ha!$B$2:$B$85="fors")*(region_annual_ha!$D$1:$Z$1>=periods!$B$4)*(region_annual_ha!$D$1:$Z$1<=periods!$C$4)*region_annual_ha!$D$2:$Z$85)/(periods!$C$4-periods!$B$4+1) -> 0 | N5: =SUMPRODUCT((region_annual_ha!$A$2:$A$85=$A5)*(region_annual_ha!$B$2:$B$85="fors")*(region_annual_ha!$D$1:$Z$1>=periods!$B$5)*(region_annual_ha!$D$1:$Z$1<=periods!$C$5)*region_annual_ha!$D$2:$Z$85)/(periods!$C$5-periods!$B$5+1) -> 0 | O5: =C5+G5+K5 -> 10578.505 | P5: =D5+H5+L5 -> 31340.269 | Q5: =E5+I5+M5 -> 150935.34 | R5: =F5+J5+N5 -> 43722.193
A6: JPN | B6: Japan | C6: =SUMPRODUCT((region_annual_ha!$A$2:$A$85=$A6)*(region_annual_ha!$B$2:$B$85="crop")*(region_annual_ha!$D$1:$Z$1>=periods!$B$2)*(region_annual_ha!$D$1:$Z$1<=periods!$C$2)*region_annual_ha!$D$2:$Z$85)/(periods!$C$2-periods!$B$2+1) -> 1596.4466 | D6: =SUMPRODUCT((region_annual_ha!$A$2:$A$85=$A6)*(region_annual_ha!$B$2:$B$85="crop")*(region_annual_ha!$D$1:$Z$1>=periods!$B$3)*(region_annual_ha!$D$1:$Z$1<=periods!$C$3)*region_annual_ha!$D$2:$Z$85)/(periods!$C$3-periods!$B$3+1) -> 1222.7145 | E6: =SUMPRODUCT((region_annual_ha!$A$2:$A$85=$A6)*(region_annual_ha!$B$2:$B$85="crop")*(region_annual_ha!$D$1:$Z$1>=periods!$B$4)*(region_annual_ha!$D$1:$Z$1<=periods!$C$4)*region_annual_ha!$D$2:$Z$85)/(periods!$C$4-periods!$B$4+1) -> 748.48155 | F6: =SUMPRODUCT((region_annual_ha!$A$2:$A$85=$A6)*(region_annual_ha!$B$2:$B$85="crop")*(region_annual_ha!$D$1:$Z$1>=periods!$B$5)*(region_annual_ha!$D$1:$Z$1<=periods!$C$5)*region_annual_ha!$D$2:$Z$85)/(periods!$C$5-periods!$B$5+1) -> 227.60148 | G6: =SUMPRODUCT((region_annual_ha!$A$2:$A$85=$A6)*(region_annual_ha!$B$2:$B$85="live")*(region_annual_ha!$D$1:$Z$1>=periods!$B$2)*(region_annual_ha!$D$1:$Z$1<=periods!$C$2)*region_annual_ha!$D$2:$Z$85)/(periods!$C$2-periods!$B$2+1) -> 119.78602 | H6: =SUMPRODUCT((region_annual_ha!$A$2:$A$85=$A6)*(region_annual_ha!$B$2:$B$85="live")*(region_annual_ha!$D$1:$Z$1>=periods!$B$3)*(region_annual_ha!$D$1:$Z$1<=periods!$C$3)*region_annual_ha!$D$2:$Z$85)/(periods!$C$3-periods!$B$3+1) -> 88.193475 | I6: =SUMPRODUCT((region_annual_ha!$A$2:$A$85=$A6)*(region_annual_ha!$B$2:$B$85="live")*(region_annual_ha!$D$1:$Z$1>=periods!$B$4)*(region_annual_ha!$D$1:$Z$1<=periods!$C$4)*region_annual_ha!$D$2:$Z$85)/(periods!$C$4-periods!$B$4+1) -> 105.4235 | J6: =SUMPRODUCT((region_annual_ha!$A$2:$A$85=$A6)*(region_annual_ha!$B$2:$B$85="live")*(region_annual_ha!$D$1:$Z$1>=periods!$B$5)*(region_annual_ha!$D$1:$Z$1<=periods!$C$5)*region_annual_ha!$D$2:$Z$85)/(periods!$C$5-periods!$B$5+1) -> 266.38853 | K6: =SUMPRODUCT((region_annual_ha!$A$2:$A$85=$A6)*(region_annual_ha!$B$2:$B$85="fors")*(region_annual_ha!$D$1:$Z$1>=periods!$B$2)*(region_annual_ha!$D$1:$Z$1<=periods!$C$2)*region_annual_ha!$D$2:$Z$85)/(periods!$C$2-periods!$B$2+1) -> 0 | L6: =SUMPRODUCT((region_annual_ha!$A$2:$A$85=$A6)*(region_annual_ha!$B$2:$B$85="fors")*(region_annual_ha!$D$1:$Z$1>=periods!$B$3)*(region_annual_ha!$D$1:$Z$1<=periods!$C$3)*region_annual_ha!$D$2:$Z$85)/(periods!$C$3-periods!$B$3+1) -> 0 | M6: =SUMPRODUCT((region_annual_ha!$A$2:$A$85=$A6)*(region_annual_ha!$B$2:$B$85="fors")*(region_annual_ha!$D$1:$Z$1>=periods!$B$4)*(region_annual_ha!$D$1:$Z$1<=periods!$C$4)*region_annual_ha!$D$2:$Z$85)/(periods!$C$4-periods!$B$4+1) -> 0 | N6: =SUMPRODUCT((region_annual_ha!$A$2:$A$85=$A6)*(region_annual_ha!$B$2:$B$85="fors")*(region_annual_ha!$D$1:$Z$1>=periods!$B$5)*(region_annual_ha!$D$1:$Z$1<=periods!$C$5)*region_annual_ha!$D$2:$Z$85)/(periods!$C$5-periods!$B$5+1) -> 0 | O6: =C6+G6+K6 -> 1716.2326 | P6: =D6+H6+L6 -> 1310.9079 | Q6: =E6+I6+M6 -> 853.90504 | R6: =F6+J6+N6 -> 493.99001
A7: ANZ | B7: Australia and New Zealand (+ rest of Oceania and rest of the world) | C7: =SUMPRODUCT((region_annual_ha!$A$2:$A$85=$A7)*(region_annual_ha!$B$2:$B$85="crop")*(region_annual_ha!$D$1:$Z$1>=periods!$B$2)*(region_annual_ha!$D$1:$Z$1<=periods!$C$2)*region_annual_ha!$D$2:$Z$85)/(periods!$C$2-periods!$B$2+1) -> 39379.243 | D7: =SUMPRODUCT((region_annual_ha!$A$2:$A$85=$A7)*(region_annual_ha!$B$2:$B$85="crop")*(region_annual_ha!$D$1:$Z$1>=periods!$B$3)*(region_annual_ha!$D$1:$Z$1<=periods!$C$3)*region_annual_ha!$D$2:$Z$85)/(periods!$C$3-periods!$B$3+1) -> 37103.197 | E7: =SUMPRODUCT((region_annual_ha!$A$2:$A$85=$A7)*(region_annual_ha!$B$2:$B$85="crop")*(region_annual_ha!$D$1:$Z$1>=periods!$B$4)*(region_annual_ha!$D$1:$Z$1<=periods!$C$4)*region_annual_ha!$D$2:$Z$85)/(periods!$C$4-periods!$B$4+1) -> 18131.262 | F7: =SUMPRODUCT((region_annual_ha!$A$2:$A$85=$A7)*(region_annual_ha!$B$2:$B$85="crop")*(region_annual_ha!$D$1:$Z$1>=periods!$B$5)*(region_annual_ha!$D$1:$Z$1<=periods!$C$5)*region_annual_ha!$D$2:$Z$85)/(periods!$C$5-periods!$B$5+1) -> 9480.5679 | G7: =SUMPRODUCT((region_annual_ha!$A$2:$A$85=$A7)*(region_annual_ha!$B$2:$B$85="live")*(region_annual_ha!$D$1:$Z$1>=periods!$B$2)*(region_annual_ha!$D$1:$Z$1<=periods!$C$2)*region_annual_ha!$D$2:$Z$85)/(periods!$C$2-periods!$B$2+1) -> 5934.1626 | H7: =SUMPRODUCT((region_annual_ha!$A$2:$A$85=$A7)*(region_annual_ha!$B$2:$B$85="live")*(region_annual_ha!$D$1:$Z$1>=periods!$B$3)*(region_annual_ha!$D$1:$Z$1<=periods!$C$3)*region_annual_ha!$D$2:$Z$85)/(periods!$C$3-periods!$B$3+1) -> 8061.7263 | I7: =SUMPRODUCT((region_annual_ha!$A$2:$A$85=$A7)*(region_annual_ha!$B$2:$B$85="live")*(region_annual_ha!$D$1:$Z$1>=periods!$B$4)*(region_annual_ha!$D$1:$Z$1<=periods!$C$4)*region_annual_ha!$D$2:$Z$85)/(periods!$C$4-periods!$B$4+1) -> 10764.456 | J7: =SUMPRODUCT((region_annual_ha!$A$2:$A$85=$A7)*(region_annual_ha!$B$2:$B$85="live")*(region_annual_ha!$D$1:$Z$1>=periods!$B$5)*(region_annual_ha!$D$1:$Z$1<=periods!$C$5)*region_annual_ha!$D$2:$Z$85)/(periods!$C$5-periods!$B$5+1) -> 10409.855 | K7: =SUMPRODUCT((region_annual_ha!$A$2:$A$85=$A7)*(region_annual_ha!$B$2:$B$85="fors")*(region_annual_ha!$D$1:$Z$1>=periods!$B$2)*(region_annual_ha!$D$1:$Z$1<=periods!$C$2)*region_annual_ha!$D$2:$Z$85)/(periods!$C$2-periods!$B$2+1) -> 14214.776 | L7: =SUMPRODUCT((region_annual_ha!$A$2:$A$85=$A7)*(region_annual_ha!$B$2:$B$85="fors")*(region_annual_ha!$D$1:$Z$1>=periods!$B$3)*(region_annual_ha!$D$1:$Z$1<=periods!$C$3)*region_annual_ha!$D$2:$Z$85)/(periods!$C$3-periods!$B$3+1) -> 3936.0003 | M7: =SUMPRODUCT((region_annual_ha!$A$2:$A$85=$A7)*(region_annual_ha!$B$2:$B$85="fors")*(region_annual_ha!$D$1:$Z$1>=periods!$B$4)*(region_annual_ha!$D$1:$Z$1<=periods!$C$4)*region_annual_ha!$D$2:$Z$85)/(periods!$C$4-periods!$B$4+1) -> 15084.351 | N7: =SUMPRODUCT((region_annual_ha!$A$2:$A$85=$A7)*(region_annual_ha!$B$2:$B$85="fors")*(region_annual_ha!$D$1:$Z$1>=periods!$B$5)*(region_annual_ha!$D$1:$Z$1<=periods!$C$5)*region_annual_ha!$D$2:$Z$85)/(periods!$C$5-periods!$B$5+1) -> 17600.927 | O7: =C7+G7+K7 -> 59528.181 | P7: =D7+H7+L7 -> 49100.923 | Q7: =E7+I7+M7 -> 43980.069 | R7: =F7+J7+N7 -> 37491.35
A8: EUR | B8: European Union 28 + EFTA | C8: =SUMPRODUCT((region_annual_ha!$A$2:$A$85=$A8)*(region_annual_ha!$B$2:$B$85="crop")*(region_annual_ha!$D$1:$Z$1>=periods!$B$2)*(region_annual_ha!$D$1:$Z$1<=periods!$C$2)*region_annual_ha!$D$2:$Z$85)/(periods!$C$2-periods!$B$2+1) -> 13010.023 | D8: =SUMPRODUCT((region_annual_ha!$A$2:$A$85=$A8)*(region_annual_ha!$B$2:$B$85="crop")*(region_annual_ha!$D$1:$Z$1>=periods!$B$3)*(region_annual_ha!$D$1:$Z$1<=periods!$C$3)*region_annual_ha!$D$2:$Z$85)/(periods!$C$3-periods!$B$3+1) -> 8716.1268 | E8: =SUMPRODUCT((region_annual_ha!$A$2:$A$85=$A8)*(region_annual_ha!$B$2:$B$85="crop")*(region_annual_ha!$D$1:$Z$1>=periods!$B$4)*(region_annual_ha!$D$1:$Z$1<=periods!$C$4)*region_annual_ha!$D$2:$Z$85)/(periods!$C$4-periods!$B$4+1) -> 9845.9764 | F8: =SUMPRODUCT((region_annual_ha!$A$2:$A$85=$A8)*(region_annual_ha!$B$2:$B$85="crop")*(region_annual_ha!$D$1:$Z$1>=periods!$B$5)*(region_annual_ha!$D$1:$Z$1<=periods!$C$5)*region_annual_ha!$D$2:$Z$85)/(periods!$C$5-periods!$B$5+1) -> 3044.7192 | G8: =SUMPRODUCT((region_annual_ha!$A$2:$A$85=$A8)*(region_annual_ha!$B$2:$B$85="live")*(region_annual_ha!$D$1:$Z$1>=periods!$B$2)*(region_annual_ha!$D$1:$Z$1<=periods!$C$2)*region_annual_ha!$D$2:$Z$85)/(periods!$C$2-periods!$B$2+1) -> 4556.2305 | H8: =SUMPRODUCT((region_annual_ha!$A$2:$A$85=$A8)*(region_annual_ha!$B$2:$B$85="live")*(region_annual_ha!$D$1:$Z$1>=periods!$B$3)*(region_annual_ha!$D$1:$Z$1<=periods!$C$3)*region_annual_ha!$D$2:$Z$85)/(periods!$C$3-periods!$B$3+1) -> 4626.6429 | I8: =SUMPRODUCT((region_annual_ha!$A$2:$A$85=$A8)*(region_annual_ha!$B$2:$B$85="live")*(region_annual_ha!$D$1:$Z$1>=periods!$B$4)*(region_annual_ha!$D$1:$Z$1<=periods!$C$4)*region_annual_ha!$D$2:$Z$85)/(periods!$C$4-periods!$B$4+1) -> 6182.3225 | J8: =SUMPRODUCT((region_annual_ha!$A$2:$A$85=$A8)*(region_annual_ha!$B$2:$B$85="live")*(region_annual_ha!$D$1:$Z$1>=periods!$B$5)*(region_annual_ha!$D$1:$Z$1<=periods!$C$5)*region_annual_ha!$D$2:$Z$85)/(periods!$C$5-periods!$B$5+1) -> 4474.4935 | K8: =SUMPRODUCT((region_annual_ha!$A$2:$A$85=$A8)*(region_annual_ha!$B$2:$B$85="fors")*(region_annual_ha!$D$1:$Z$1>=periods!$B$2)*(region_annual_ha!$D$1:$Z$1<=periods!$C$2)*region_annual_ha!$D$2:$Z$85)/(periods!$C$2-periods!$B$2+1) -> 20503.138 | L8: =SUMPRODUCT((region_annual_ha!$A$2:$A$85=$A8)*(region_annual_ha!$B$2:$B$85="fors")*(region_annual_ha!$D$1:$Z$1>=periods!$B$3)*(region_annual_ha!$D$1:$Z$1<=periods!$C$3)*region_annual_ha!$D$2:$Z$85)/(periods!$C$3-periods!$B$3+1) -> 5932.0249 | M8: =SUMPRODUCT((region_annual_ha!$A$2:$A$85=$A8)*(region_annual_ha!$B$2:$B$85="fors")*(region_annual_ha!$D$1:$Z$1>=periods!$B$4)*(region_annual_ha!$D$1:$Z$1<=periods!$C$4)*region_annual_ha!$D$2:$Z$85)/(periods!$C$4-periods!$B$4+1) -> 5923.6609 | N8: =SUMPRODUCT((region_annual_ha!$A$2:$A$85=$A8)*(region_annual_ha!$B$2:$B$85="fors")*(region_annual_ha!$D$1:$Z$1>=periods!$B$5)*(region_annual_ha!$D$1:$Z$1<=periods!$C$5)*region_annual_ha!$D$2:$Z$85)/(periods!$C$5-periods!$B$5+1) -> 6499.396 | O8: =C8+G8+K8 -> 38069.391 | P8: =D8+H8+L8 -> 19274.795 | Q8: =E8+I8+M8 -> 21951.96 | R8: =F8+J8+N8 -> 14018.609
A9: ROE | B9: Rest of Europe and Central Asia (incl. Turkey) | C9: =SUMPRODUCT((region_annual_ha!$A$2:$A$85=$A9)*(region_annual_ha!$B$2:$B$85="crop")*(region_annual_ha!$D$1:$Z$1>=periods!$B$2)*(region_annual_ha!$D$1:$Z$1<=periods!$C$2)*region_annual_ha!$D$2:$Z$85)/(periods!$C$2-periods!$B$2+1) -> 2470.8627 | D9: =SUMPRODUCT((region_annual_ha!$A$2:$A$85=$A9)*(region_annual_ha!$B$2:$B$85="crop")*(region_annual_ha!$D$1:$Z$1>=periods!$B$3)*(region_annual_ha!$D$1:$Z$1<=periods!$C$3)*region_annual_ha!$D$2:$Z$85)/(periods!$C$3-periods!$B$3+1) -> 3345.8874 | E9: =SUMPRODUCT((region_annual_ha!$A$2:$A$85=$A9)*(region_annual_ha!$B$2:$B$85="crop")*(region_annual_ha!$D$1:$Z$1>=periods!$B$4)*(region_annual_ha!$D$1:$Z$1<=periods!$C$4)*region_annual_ha!$D$2:$Z$85)/(periods!$C$4-periods!$B$4+1) -> 5774.5608 | F9: =SUMPRODUCT((region_annual_ha!$A$2:$A$85=$A9)*(region_annual_ha!$B$2:$B$85="crop")*(region_annual_ha!$D$1:$Z$1>=periods!$B$5)*(region_annual_ha!$D$1:$Z$1<=periods!$C$5)*region_annual_ha!$D$2:$Z$85)/(periods!$C$5-periods!$B$5+1) -> 975.02984 | G9: =SUMPRODUCT((region_annual_ha!$A$2:$A$85=$A9)*(region_annual_ha!$B$2:$B$85="live")*(region_annual_ha!$D$1:$Z$1>=periods!$B$2)*(region_annual_ha!$D$1:$Z$1<=periods!$C$2)*region_annual_ha!$D$2:$Z$85)/(periods!$C$2-periods!$B$2+1) -> 1115.7724 | H9: =SUMPRODUCT((region_annual_ha!$A$2:$A$85=$A9)*(region_annual_ha!$B$2:$B$85="live")*(region_annual_ha!$D$1:$Z$1>=periods!$B$3)*(region_annual_ha!$D$1:$Z$1<=periods!$C$3)*region_annual_ha!$D$2:$Z$85)/(periods!$C$3-periods!$B$3+1) -> 457.42877 | I9: =SUMPRODUCT((region_annual_ha!$A$2:$A$85=$A9)*(region_annual_ha!$B$2:$B$85="live")*(region_annual_ha!$D$1:$Z$1>=periods!$B$4)*(region_annual_ha!$D$1:$Z$1<=periods!$C$4)*region_annual_ha!$D$2:$Z$85)/(periods!$C$4-periods!$B$4+1) -> 584.45781 | J9: =SUMPRODUCT((region_annual_ha!$A$2:$A$85=$A9)*(region_annual_ha!$B$2:$B$85="live")*(region_annual_ha!$D$1:$Z$1>=periods!$B$5)*(region_annual_ha!$D$1:$Z$1<=periods!$C$5)*region_annual_ha!$D$2:$Z$85)/(periods!$C$5-periods!$B$5+1) -> 565.85134 | K9: =SUMPRODUCT((region_annual_ha!$A$2:$A$85=$A9)*(region_annual_ha!$B$2:$B$85="fors")*(region_annual_ha!$D$1:$Z$1>=periods!$B$2)*(region_annual_ha!$D$1:$Z$1<=periods!$C$2)*region_annual_ha!$D$2:$Z$85)/(periods!$C$2-periods!$B$2+1) -> 5791.5992 | L9: =SUMPRODUCT((region_annual_ha!$A$2:$A$85=$A9)*(region_annual_ha!$B$2:$B$85="fors")*(region_annual_ha!$D$1:$Z$1>=periods!$B$3)*(region_annual_ha!$D$1:$Z$1<=periods!$C$3)*region_annual_ha!$D$2:$Z$85)/(periods!$C$3-periods!$B$3+1) -> 5723.6248 | M9: =SUMPRODUCT((region_annual_ha!$A$2:$A$85=$A9)*(region_annual_ha!$B$2:$B$85="fors")*(region_annual_ha!$D$1:$Z$1>=periods!$B$4)*(region_annual_ha!$D$1:$Z$1<=periods!$C$4)*region_annual_ha!$D$2:$Z$85)/(periods!$C$4-periods!$B$4+1) -> 1885.3676 | N9: =SUMPRODUCT((region_annual_ha!$A$2:$A$85=$A9)*(region_annual_ha!$B$2:$B$85="fors")*(region_annual_ha!$D$1:$Z$1>=periods!$B$5)*(region_annual_ha!$D$1:$Z$1<=periods!$C$5)*region_annual_ha!$D$2:$Z$85)/(periods!$C$5-periods!$B$5+1) -> 1736.5691 | O9: =C9+G9+K9 -> 9378.2342 | P9: =D9+H9+L9 -> 9526.9409 | Q9: =E9+I9+M9 -> 8244.3862 | R9: =F9+J9+N9 -> 3277.4503
A10: RUS | B10: Russia | C10: =SUMPRODUCT((region_annual_ha!$A$2:$A$85=$A10)*(region_annual_ha!$B$2:$B$85="crop")*(region_annual_ha!$D$1:$Z$1>=periods!$B$2)*(region_annual_ha!$D$1:$Z$1<=periods!$C$2)*region_annual_ha!$D$2:$Z$85)/(periods!$C$2-periods!$B$2+1) -> 6412.9035 | D10: =SUMPRODUCT((region_annual_ha!$A$2:$A$85=$A10)*(region_annual_ha!$B$2:$B$85="crop")*(region_annual_ha!$D$1:$Z$1>=periods!$B$3)*(region_annual_ha!$D$1:$Z$1<=periods!$C$3)*region_annual_ha!$D$2:$Z$85)/(periods!$C$3-periods!$B$3+1) -> 6589.639 | E10: =SUMPRODUCT((region_annual_ha!$A$2:$A$85=$A10)*(region_annual_ha!$B$2:$B$85="crop")*(region_annual_ha!$D$1:$Z$1>=periods!$B$4)*(region_annual_ha!$D$1:$Z$1<=periods!$C$4)*region_annual_ha!$D$2:$Z$85)/(periods!$C$4-periods!$B$4+1) -> 4938.2694 | F10: =SUMPRODUCT((region_annual_ha!$A$2:$A$85=$A10)*(region_annual_ha!$B$2:$B$85="crop")*(region_annual_ha!$D$1:$Z$1>=periods!$B$5)*(region_annual_ha!$D$1:$Z$1<=periods!$C$5)*region_annual_ha!$D$2:$Z$85)/(periods!$C$5-periods!$B$5+1) -> 1116.5535 | G10: =SUMPRODUCT((region_annual_ha!$A$2:$A$85=$A10)*(region_annual_ha!$B$2:$B$85="live")*(region_annual_ha!$D$1:$Z$1>=periods!$B$2)*(region_annual_ha!$D$1:$Z$1<=periods!$C$2)*region_annual_ha!$D$2:$Z$85)/(periods!$C$2-periods!$B$2+1) -> 9323.8304 | H10: =SUMPRODUCT((region_annual_ha!$A$2:$A$85=$A10)*(region_annual_ha!$B$2:$B$85="live")*(region_annual_ha!$D$1:$Z$1>=periods!$B$3)*(region_annual_ha!$D$1:$Z$1<=periods!$C$3)*region_annual_ha!$D$2:$Z$85)/(periods!$C$3-periods!$B$3+1) -> 9952.179 | I10: =SUMPRODUCT((region_annual_ha!$A$2:$A$85=$A10)*(region_annual_ha!$B$2:$B$85="live")*(region_annual_ha!$D$1:$Z$1>=periods!$B$4)*(region_annual_ha!$D$1:$Z$1<=periods!$C$4)*region_annual_ha!$D$2:$Z$85)/(periods!$C$4-periods!$B$4+1) -> 4037.872 | J10: =SUMPRODUCT((region_annual_ha!$A$2:$A$85=$A10)*(region_annual_ha!$B$2:$B$85="live")*(region_annual_ha!$D$1:$Z$1>=periods!$B$5)*(region_annual_ha!$D$1:$Z$1<=periods!$C$5)*region_annual_ha!$D$2:$Z$85)/(periods!$C$5-periods!$B$5+1) -> 1994.1205 | K10: =SUMPRODUCT((region_annual_ha!$A$2:$A$85=$A10)*(region_annual_ha!$B$2:$B$85="fors")*(region_annual_ha!$D$1:$Z$1>=periods!$B$2)*(region_annual_ha!$D$1:$Z$1<=periods!$C$2)*region_annual_ha!$D$2:$Z$85)/(periods!$C$2-periods!$B$2+1) -> 0 | L10: =SUMPRODUCT((region_annual_ha!$A$2:$A$85=$A10)*(region_annual_ha!$B$2:$B$85="fors")*(region_annual_ha!$D$1:$Z$1>=periods!$B$3)*(region_annual_ha!$D$1:$Z$1<=periods!$C$3)*region_annual_ha!$D$2:$Z$85)/(periods!$C$3-periods!$B$3+1) -> 0 | M10: =SUMPRODUCT((region_annual_ha!$A$2:$A$85=$A10)*(region_annual_ha!$B$2:$B$85="fors")*(region_annual_ha!$D$1:$Z$1>=periods!$B$4)*(region_annual_ha!$D$1:$Z$1<=periods!$C$4)*region_annual_ha!$D$2:$Z$85)/(periods!$C$4-periods!$B$4+1) -> 0 | N10: =SUMPRODUCT((region_annual_ha!$A$2:$A$85=$A10)*(region_annual_ha!$B$2:$B$85="fors")*(region_annual_ha!$D$1:$Z$1>=periods!$B$5)*(region_annual_ha!$D$1:$Z$1<=periods!$C$5)*region_annual_ha!$D$2:$Z$85)/(periods!$C$5-periods!$B$5+1) -> 0 | O10: =C10+G10+K10 -> 15736.734 | P10: =D10+H10+L10 -> 16541.818 | Q10: =E10+I10+M10 -> 8976.1413 | R10: =F10+J10+N10 -> 3110.674
A11: ASI | B11: Dynamic Asia (Southeast Asia) | C11: =SUMPRODUCT((region_annual_ha!$A$2:$A$85=$A11)*(region_annual_ha!$B$2:$B$85="crop")*(region_annual_ha!$D$1:$Z$1>=periods!$B$2)*(region_annual_ha!$D$1:$Z$1<=periods!$C$2)*region_annual_ha!$D$2:$Z$85)/(periods!$C$2-periods!$B$2+1) -> 230627.71 | D11: =SUMPRODUCT((region_annual_ha!$A$2:$A$85=$A11)*(region_annual_ha!$B$2:$B$85="crop")*(region_annual_ha!$D$1:$Z$1>=periods!$B$3)*(region_annual_ha!$D$1:$Z$1<=periods!$C$3)*region_annual_ha!$D$2:$Z$85)/(periods!$C$3-periods!$B$3+1) -> 201406.34 | E11: =SUMPRODUCT((region_annual_ha!$A$2:$A$85=$A11)*(region_annual_ha!$B$2:$B$85="crop")*(region_annual_ha!$D$1:$Z$1>=periods!$B$4)*(region_annual_ha!$D$1:$Z$1<=periods!$C$4)*region_annual_ha!$D$2:$Z$85)/(periods!$C$4-periods!$B$4+1) -> 190319.42 | F11: =SUMPRODUCT((region_annual_ha!$A$2:$A$85=$A11)*(region_annual_ha!$B$2:$B$85="crop")*(region_annual_ha!$D$1:$Z$1>=periods!$B$5)*(region_annual_ha!$D$1:$Z$1<=periods!$C$5)*region_annual_ha!$D$2:$Z$85)/(periods!$C$5-periods!$B$5+1) -> 100011.91 | G11: =SUMPRODUCT((region_annual_ha!$A$2:$A$85=$A11)*(region_annual_ha!$B$2:$B$85="live")*(region_annual_ha!$D$1:$Z$1>=periods!$B$2)*(region_annual_ha!$D$1:$Z$1<=periods!$C$2)*region_annual_ha!$D$2:$Z$85)/(periods!$C$2-periods!$B$2+1) -> 13136.083 | H11: =SUMPRODUCT((region_annual_ha!$A$2:$A$85=$A11)*(region_annual_ha!$B$2:$B$85="live")*(region_annual_ha!$D$1:$Z$1>=periods!$B$3)*(region_annual_ha!$D$1:$Z$1<=periods!$C$3)*region_annual_ha!$D$2:$Z$85)/(periods!$C$3-periods!$B$3+1) -> 21613.721 | I11: =SUMPRODUCT((region_annual_ha!$A$2:$A$85=$A11)*(region_annual_ha!$B$2:$B$85="live")*(region_annual_ha!$D$1:$Z$1>=periods!$B$4)*(region_annual_ha!$D$1:$Z$1<=periods!$C$4)*region_annual_ha!$D$2:$Z$85)/(periods!$C$4-periods!$B$4+1) -> 26363.798 | J11: =SUMPRODUCT((region_annual_ha!$A$2:$A$85=$A11)*(region_annual_ha!$B$2:$B$85="live")*(region_annual_ha!$D$1:$Z$1>=periods!$B$5)*(region_annual_ha!$D$1:$Z$1<=periods!$C$5)*region_annual_ha!$D$2:$Z$85)/(periods!$C$5-periods!$B$5+1) -> 46822.172 | K11: =SUMPRODUCT((region_annual_ha!$A$2:$A$85=$A11)*(region_annual_ha!$B$2:$B$85="fors")*(region_annual_ha!$D$1:$Z$1>=periods!$B$2)*(region_annual_ha!$D$1:$Z$1<=periods!$C$2)*region_annual_ha!$D$2:$Z$85)/(periods!$C$2-periods!$B$2+1) -> 34765.77 | L11: =SUMPRODUCT((region_annual_ha!$A$2:$A$85=$A11)*(region_annual_ha!$B$2:$B$85="fors")*(region_annual_ha!$D$1:$Z$1>=periods!$B$3)*(region_annual_ha!$D$1:$Z$1<=periods!$C$3)*region_annual_ha!$D$2:$Z$85)/(periods!$C$3-periods!$B$3+1) -> 40975.702 | M11: =SUMPRODUCT((region_annual_ha!$A$2:$A$85=$A11)*(region_annual_ha!$B$2:$B$85="fors")*(region_annual_ha!$D$1:$Z$1>=periods!$B$4)*(region_annual_ha!$D$1:$Z$1<=periods!$C$4)*region_annual_ha!$D$2:$Z$85)/(periods!$C$4-periods!$B$4+1) -> 2400.5911 | N11: =SUMPRODUCT((region_annual_ha!$A$2:$A$85=$A11)*(region_annual_ha!$B$2:$B$85="fors")*(region_annual_ha!$D$1:$Z$1>=periods!$B$5)*(region_annual_ha!$D$1:$Z$1<=periods!$C$5)*region_annual_ha!$D$2:$Z$85)/(periods!$C$5-periods!$B$5+1) -> 1587.8425 | O11: =C11+G11+K11 -> 278529.56 | P11: =D11+H11+L11 -> 263995.76 | Q11: =E11+I11+M11 -> 219083.81 | R11: =F11+J11+N11 -> 148421.92
A12: CHN | B12: China and Hong Kong | C12: =SUMPRODUCT((region_annual_ha!$A$2:$A$85=$A12)*(region_annual_ha!$B$2:$B$85="crop")*(region_annual_ha!$D$1:$Z$1>=periods!$B$2)*(region_annual_ha!$D$1:$Z$1<=periods!$C$2)*region_annual_ha!$D$2:$Z$85)/(periods!$C$2-periods!$B$2+1) -> 18664.729 | D12: =SUMPRODUCT((region_annual_ha!$A$2:$A$85=$A12)*(region_annual_ha!$B$2:$B$85="crop")*(region_annual_ha!$D$1:$Z$1>=periods!$B$3)*(region_annual_ha!$D$1:$Z$1<=periods!$C$3)*region_annual_ha!$D$2:$Z$85)/(periods!$C$3-periods!$B$3+1) -> 13218.081 | E12: =SUMPRODUCT((region_annual_ha!$A$2:$A$85=$A12)*(region_annual_ha!$B$2:$B$85="crop")*(region_annual_ha!$D$1:$Z$1>=periods!$B$4)*(region_annual_ha!$D$1:$Z$1<=periods!$C$4)*region_annual_ha!$D$2:$Z$85)/(periods!$C$4-periods!$B$4+1) -> 29911.338 | F12: =SUMPRODUCT((region_annual_ha!$A$2:$A$85=$A12)*(region_annual_ha!$B$2:$B$85="crop")*(region_annual_ha!$D$1:$Z$1>=periods!$B$5)*(region_annual_ha!$D$1:$Z$1<=periods!$C$5)*region_annual_ha!$D$2:$Z$85)/(periods!$C$5-periods!$B$5+1) -> 21290.316 | G12: =SUMPRODUCT((region_annual_ha!$A$2:$A$85=$A12)*(region_annual_ha!$B$2:$B$85="live")*(region_annual_ha!$D$1:$Z$1>=periods!$B$2)*(region_annual_ha!$D$1:$Z$1<=periods!$C$2)*region_annual_ha!$D$2:$Z$85)/(periods!$C$2-periods!$B$2+1) -> 49718.418 | H12: =SUMPRODUCT((region_annual_ha!$A$2:$A$85=$A12)*(region_annual_ha!$B$2:$B$85="live")*(region_annual_ha!$D$1:$Z$1>=periods!$B$3)*(region_annual_ha!$D$1:$Z$1<=periods!$C$3)*region_annual_ha!$D$2:$Z$85)/(periods!$C$3-periods!$B$3+1) -> 48731.823 | I12: =SUMPRODUCT((region_annual_ha!$A$2:$A$85=$A12)*(region_annual_ha!$B$2:$B$85="live")*(region_annual_ha!$D$1:$Z$1>=periods!$B$4)*(region_annual_ha!$D$1:$Z$1<=periods!$C$4)*region_annual_ha!$D$2:$Z$85)/(periods!$C$4-periods!$B$4+1) -> 39208.584 | J12: =SUMPRODUCT((region_annual_ha!$A$2:$A$85=$A12)*(region_annual_ha!$B$2:$B$85="live")*(region_annual_ha!$D$1:$Z$1>=periods!$B$5)*(region_annual_ha!$D$1:$Z$1<=periods!$C$5)*region_annual_ha!$D$2:$Z$85)/(periods!$C$5-periods!$B$5+1) -> 22837.236 | K12: =SUMPRODUCT((region_annual_ha!$A$2:$A$85=$A12)*(region_annual_ha!$B$2:$B$85="fors")*(region_annual_ha!$D$1:$Z$1>=periods!$B$2)*(region_annual_ha!$D$1:$Z$1<=periods!$C$2)*region_annual_ha!$D$2:$Z$85)/(periods!$C$2-periods!$B$2+1) -> 213523.33 | L12: =SUMPRODUCT((region_annual_ha!$A$2:$A$85=$A12)*(region_annual_ha!$B$2:$B$85="fors")*(region_annual_ha!$D$1:$Z$1>=periods!$B$3)*(region_annual_ha!$D$1:$Z$1<=periods!$C$3)*region_annual_ha!$D$2:$Z$85)/(periods!$C$3-periods!$B$3+1) -> 235829.55 | M12: =SUMPRODUCT((region_annual_ha!$A$2:$A$85=$A12)*(region_annual_ha!$B$2:$B$85="fors")*(region_annual_ha!$D$1:$Z$1>=periods!$B$4)*(region_annual_ha!$D$1:$Z$1<=periods!$C$4)*region_annual_ha!$D$2:$Z$85)/(periods!$C$4-periods!$B$4+1) -> 347362.51 | N12: =SUMPRODUCT((region_annual_ha!$A$2:$A$85=$A12)*(region_annual_ha!$B$2:$B$85="fors")*(region_annual_ha!$D$1:$Z$1>=periods!$B$5)*(region_annual_ha!$D$1:$Z$1<=periods!$C$5)*region_annual_ha!$D$2:$Z$85)/(periods!$C$5-periods!$B$5+1) -> 395369.76 | O12: =C12+G12+K12 -> 281906.48 | P12: =D12+H12+L12 -> 297779.45 | Q12: =E12+I12+M12 -> 416482.44 | R12: =F12+J12+N12 -> 439497.31
A13: IND | B13: India | C13: =SUMPRODUCT((region_annual_ha!$A$2:$A$85=$A13)*(region_annual_ha!$B$2:$B$85="crop")*(region_annual_ha!$D$1:$Z$1>=periods!$B$2)*(region_annual_ha!$D$1:$Z$1<=periods!$C$2)*region_annual_ha!$D$2:$Z$85)/(periods!$C$2-periods!$B$2+1) -> 32946.971 | D13: =SUMPRODUCT((region_annual_ha!$A$2:$A$85=$A13)*(region_annual_ha!$B$2:$B$85="crop")*(region_annual_ha!$D$1:$Z$1>=periods!$B$3)*(region_annual_ha!$D$1:$Z$1<=periods!$C$3)*region_annual_ha!$D$2:$Z$85)/(periods!$C$3-periods!$B$3+1) -> 40650.303 | E13: =SUMPRODUCT((region_annual_ha!$A$2:$A$85=$A13)*(region_annual_ha!$B$2:$B$85="crop")*(region_annual_ha!$D$1:$Z$1>=periods!$B$4)*(region_annual_ha!$D$1:$Z$1<=periods!$C$4)*region_annual_ha!$D$2:$Z$85)/(periods!$C$4-periods!$B$4+1) -> 57358.325 | F13: =SUMPRODUCT((region_annual_ha!$A$2:$A$85=$A13)*(region_annual_ha!$B$2:$B$85="crop")*(region_annual_ha!$D$1:$Z$1>=periods!$B$5)*(region_annual_ha!$D$1:$Z$1<=periods!$C$5)*region_annual_ha!$D$2:$Z$85)/(periods!$C$5-periods!$B$5+1) -> 115079.46 | G13: =SUMPRODUCT((region_annual_ha!$A$2:$A$85=$A13)*(region_annual_ha!$B$2:$B$85="live")*(region_annual_ha!$D$1:$Z$1>=periods!$B$2)*(region_annual_ha!$D$1:$Z$1<=periods!$C$2)*region_annual_ha!$D$2:$Z$85)/(periods!$C$2-periods!$B$2+1) -> 9553.5266 | H13: =SUMPRODUCT((region_annual_ha!$A$2:$A$85=$A13)*(region_annual_ha!$B$2:$B$85="live")*(region_annual_ha!$D$1:$Z$1>=periods!$B$3)*(region_annual_ha!$D$1:$Z$1<=periods!$C$3)*region_annual_ha!$D$2:$Z$85)/(periods!$C$3-periods!$B$3+1) -> 40449.563 | I13: =SUMPRODUCT((region_annual_ha!$A$2:$A$85=$A13)*(region_annual_ha!$B$2:$B$85="live")*(region_annual_ha!$D$1:$Z$1>=periods!$B$4)*(region_annual_ha!$D$1:$Z$1<=periods!$C$4)*region_annual_ha!$D$2:$Z$85)/(periods!$C$4-periods!$B$4+1) -> 70922.325 | J13: =SUMPRODUCT((region_annual_ha!$A$2:$A$85=$A13)*(region_annual_ha!$B$2:$B$85="live")*(region_annual_ha!$D$1:$Z$1>=periods!$B$5)*(region_annual_ha!$D$1:$Z$1<=periods!$C$5)*region_annual_ha!$D$2:$Z$85)/(periods!$C$5-periods!$B$5+1) -> 2256.8525 | K13: =SUMPRODUCT((region_annual_ha!$A$2:$A$85=$A13)*(region_annual_ha!$B$2:$B$85="fors")*(region_annual_ha!$D$1:$Z$1>=periods!$B$2)*(region_annual_ha!$D$1:$Z$1<=periods!$C$2)*region_annual_ha!$D$2:$Z$85)/(periods!$C$2-periods!$B$2+1) -> 7637.1535 | L13: =SUMPRODUCT((region_annual_ha!$A$2:$A$85=$A13)*(region_annual_ha!$B$2:$B$85="fors")*(region_annual_ha!$D$1:$Z$1>=periods!$B$3)*(region_annual_ha!$D$1:$Z$1<=periods!$C$3)*region_annual_ha!$D$2:$Z$85)/(periods!$C$3-periods!$B$3+1) -> 10193.116 | M13: =SUMPRODUCT((region_annual_ha!$A$2:$A$85=$A13)*(region_annual_ha!$B$2:$B$85="fors")*(region_annual_ha!$D$1:$Z$1>=periods!$B$4)*(region_annual_ha!$D$1:$Z$1<=periods!$C$4)*region_annual_ha!$D$2:$Z$85)/(periods!$C$4-periods!$B$4+1) -> 9940.0494 | N13: =SUMPRODUCT((region_annual_ha!$A$2:$A$85=$A13)*(region_annual_ha!$B$2:$B$85="fors")*(region_annual_ha!$D$1:$Z$1>=periods!$B$5)*(region_annual_ha!$D$1:$Z$1<=periods!$C$5)*region_annual_ha!$D$2:$Z$85)/(periods!$C$5-periods!$B$5+1) -> 8559.502 | O13: =C13+G13+K13 -> 50137.651 | P13: =D13+H13+L13 -> 91292.982 | Q13: =E13+I13+M13 -> 138220.7 | R13: =F13+J13+N13 -> 125895.82
A14: BRA | B14: Brazil | C14: =SUMPRODUCT((region_annual_ha!$A$2:$A$85=$A14)*(region_annual_ha!$B$2:$B$85="crop")*(region_annual_ha!$D$1:$Z$1>=periods!$B$2)*(region_annual_ha!$D$1:$Z$1<=periods!$C$2)*region_annual_ha!$D$2:$Z$85)/(periods!$C$2-periods!$B$2+1) -> 220424.47 | D14: =SUMPRODUCT((region_annual_ha!$A$2:$A$85=$A14)*(region_annual_ha!$B$2:$B$85="crop")*(region_annual_ha!$D$1:$Z$1>=periods!$B$3)*(region_annual_ha!$D$1:$Z$1<=periods!$C$3)*region_annual_ha!$D$2:$Z$85)/(periods!$C$3-periods!$B$3+1) -> 227997.75 | E14: =SUMPRODUCT((region_annual_ha!$A$2:$A$85=$A14)*(region_annual_ha!$B$2:$B$85="crop")*(region_annual_ha!$D$1:$Z$1>=periods!$B$4)*(region_annual_ha!$D$1:$Z$1<=periods!$C$4)*region_annual_ha!$D$2:$Z$85)/(periods!$C$4-periods!$B$4+1) -> 168835.6 | F14: =SUMPRODUCT((region_annual_ha!$A$2:$A$85=$A14)*(region_annual_ha!$B$2:$B$85="crop")*(region_annual_ha!$D$1:$Z$1>=periods!$B$5)*(region_annual_ha!$D$1:$Z$1<=periods!$C$5)*region_annual_ha!$D$2:$Z$85)/(periods!$C$5-periods!$B$5+1) -> 139104.72 | G14: =SUMPRODUCT((region_annual_ha!$A$2:$A$85=$A14)*(region_annual_ha!$B$2:$B$85="live")*(region_annual_ha!$D$1:$Z$1>=periods!$B$2)*(region_annual_ha!$D$1:$Z$1<=periods!$C$2)*region_annual_ha!$D$2:$Z$85)/(periods!$C$2-periods!$B$2+1) -> 1187228.2 | H14: =SUMPRODUCT((region_annual_ha!$A$2:$A$85=$A14)*(region_annual_ha!$B$2:$B$85="live")*(region_annual_ha!$D$1:$Z$1>=periods!$B$3)*(region_annual_ha!$D$1:$Z$1<=periods!$C$3)*region_annual_ha!$D$2:$Z$85)/(periods!$C$3-periods!$B$3+1) -> 1023102.1 | I14: =SUMPRODUCT((region_annual_ha!$A$2:$A$85=$A14)*(region_annual_ha!$B$2:$B$85="live")*(region_annual_ha!$D$1:$Z$1>=periods!$B$4)*(region_annual_ha!$D$1:$Z$1<=periods!$C$4)*region_annual_ha!$D$2:$Z$85)/(periods!$C$4-periods!$B$4+1) -> 1463738.5 | J14: =SUMPRODUCT((region_annual_ha!$A$2:$A$85=$A14)*(region_annual_ha!$B$2:$B$85="live")*(region_annual_ha!$D$1:$Z$1>=periods!$B$5)*(region_annual_ha!$D$1:$Z$1<=periods!$C$5)*region_annual_ha!$D$2:$Z$85)/(periods!$C$5-periods!$B$5+1) -> 1470065.7 | K14: =SUMPRODUCT((region_annual_ha!$A$2:$A$85=$A14)*(region_annual_ha!$B$2:$B$85="fors")*(region_annual_ha!$D$1:$Z$1>=periods!$B$2)*(region_annual_ha!$D$1:$Z$1<=periods!$C$2)*region_annual_ha!$D$2:$Z$85)/(periods!$C$2-periods!$B$2+1) -> 12505.07 | L14: =SUMPRODUCT((region_annual_ha!$A$2:$A$85=$A14)*(region_annual_ha!$B$2:$B$85="fors")*(region_annual_ha!$D$1:$Z$1>=periods!$B$3)*(region_annual_ha!$D$1:$Z$1<=periods!$C$3)*region_annual_ha!$D$2:$Z$85)/(periods!$C$3-periods!$B$3+1) -> 31881.63 | M14: =SUMPRODUCT((region_annual_ha!$A$2:$A$85=$A14)*(region_annual_ha!$B$2:$B$85="fors")*(region_annual_ha!$D$1:$Z$1>=periods!$B$4)*(region_annual_ha!$D$1:$Z$1<=periods!$C$4)*region_annual_ha!$D$2:$Z$85)/(periods!$C$4-periods!$B$4+1) -> 47954.496 | N14: =SUMPRODUCT((region_annual_ha!$A$2:$A$85=$A14)*(region_annual_ha!$B$2:$B$85="fors")*(region_annual_ha!$D$1:$Z$1>=periods!$B$5)*(region_annual_ha!$D$1:$Z$1<=periods!$C$5)*region_annual_ha!$D$2:$Z$85)/(periods!$C$5-periods!$B$5+1) -> 45170.02 | O14: =C14+G14+K14 -> 1420157.8 | P14: =D14+H14+L14 -> 1282981.4 | Q14: =E14+I14+M14 -> 1680528.6 | R14: =F14+J14+N14 -> 1654340.5
... A30: IDZ | B30: Indonesia | C30: =SUMPRODUCT((region_annual_ha!$A$2:$A$85=$A30)*(region_annual_ha!$B$2:$B$85="crop")*(region_annual_ha!$D$1:$Z$1>=periods!$B$2)*(region_annual_ha!$D$1:$Z$1<=periods!$C$2)*region_annual_ha!$D$2:$Z$85)/(periods!$C$2-periods!$B$2+1) -> 715876.52 | D30: =SUMPRODUCT((region_annual_ha!$A$2:$A$85=$A30)*(region_annual_ha!$B$2:$B$85="crop")*(region_annual_ha!$D$1:$Z$1>=periods!$B$3)*(region_annual_ha!$D$1:$Z$1<=periods!$C$3)*region_annual_ha!$D$2:$Z$85)/(periods!$C$3-periods!$B$3+1) -> 639106.16 | E30: =SUMPRODUCT((region_annual_ha!$A$2:$A$85=$A30)*(region_annual_ha!$B$2:$B$85="crop")*(region_annual_ha!$D$1:$Z$1>=periods!$B$4)*(region_annual_ha!$D$1:$Z$1<=periods!$C$4)*region_annual_ha!$D$2:$Z$85)/(periods!$C$4-periods!$B$4+1) -> 278707.3 | F30: =SUMPRODUCT((region_annual_ha!$A$2:$A$85=$A30)*(region_annual_ha!$B$2:$B$85="crop")*(region_annual_ha!$D$1:$Z$1>=periods!$B$5)*(region_annual_ha!$D$1:$Z$1<=periods!$C$5)*region_annual_ha!$D$2:$Z$85)/(periods!$C$5-periods!$B$5+1) -> 84932.949 | G30: =SUMPRODUCT((region_annual_ha!$A$2:$A$85=$A30)*(region_annual_ha!$B$2:$B$85="live")*(region_annual_ha!$D$1:$Z$1>=periods!$B$2)*(region_annual_ha!$D$1:$Z$1<=periods!$C$2)*region_annual_ha!$D$2:$Z$85)/(periods!$C$2-periods!$B$2+1) -> 5493.4137 | H30: =SUMPRODUCT((region_annual_ha!$A$2:$A$85=$A30)*(region_annual_ha!$B$2:$B$85="live")*(region_annual_ha!$D$1:$Z$1>=periods!$B$3)*(region_annual_ha!$D$1:$Z$1<=periods!$C$3)*region_annual_ha!$D$2:$Z$85)/(periods!$C$3-periods!$B$3+1) -> 13800.15 | I30: =SUMPRODUCT((region_annual_ha!$A$2:$A$85=$A30)*(region_annual_ha!$B$2:$B$85="live")*(region_annual_ha!$D$1:$Z$1>=periods!$B$4)*(region_annual_ha!$D$1:$Z$1<=periods!$C$4)*region_annual_ha!$D$2:$Z$85)/(periods!$C$4-periods!$B$4+1) -> 8473.3453 | J30: =SUMPRODUCT((region_annual_ha!$A$2:$A$85=$A30)*(region_annual_ha!$B$2:$B$85="live")*(region_annual_ha!$D$1:$Z$1>=periods!$B$5)*(region_annual_ha!$D$1:$Z$1<=periods!$C$5)*region_annual_ha!$D$2:$Z$85)/(periods!$C$5-periods!$B$5+1) -> 10340.489 | K30: =SUMPRODUCT((region_annual_ha!$A$2:$A$85=$A30)*(region_annual_ha!$B$2:$B$85="fors")*(region_annual_ha!$D$1:$Z$1>=periods!$B$2)*(region_annual_ha!$D$1:$Z$1<=periods!$C$2)*region_annual_ha!$D$2:$Z$85)/(periods!$C$2-periods!$B$2+1) -> 78423.537 | L30: =SUMPRODUCT((region_annual_ha!$A$2:$A$85=$A30)*(region_annual_ha!$B$2:$B$85="fors")*(region_annual_ha!$D$1:$Z$1>=periods!$B$3)*(region_annual_ha!$D$1:$Z$1<=periods!$C$3)*region_annual_ha!$D$2:$Z$85)/(periods!$C$3-periods!$B$3+1) -> 76384.355 | M30: =SUMPRODUCT((region_annual_ha!$A$2:$A$85=$A30)*(region_annual_ha!$B$2:$B$85="fors")*(region_annual_ha!$D$1:$Z$1>=periods!$B$4)*(region_annual_ha!$D$1:$Z$1<=periods!$C$4)*region_annual_ha!$D$2:$Z$85)/(periods!$C$4-periods!$B$4+1) -> 42908.191 | N30: =SUMPRODUCT((region_annual_ha!$A$2:$A$85=$A30)*(region_annual_ha!$B$2:$B$85="fors")*(region_annual_ha!$D$1:$Z$1>=periods!$B$5)*(region_annual_ha!$D$1:$Z$1<=periods!$C$5)*region_annual_ha!$D$2:$Z$85)/(periods!$C$5-periods!$B$5+1) -> 7364.3831 | O30: =C30+G30+K30 -> 799793.47 | P30: =D30+H30+L30 -> 729290.67 | Q30: =E30+I30+M30 -> 330088.83 | R30: =F30+J30+N30 -> 102637.82
A31: World | B31: sum of the 28 regions | C31: =SUM(C3:C30) -> 3293896.4 | D31: =SUM(D3:D30) -> 3087252.9 | E31: =SUM(E3:E30) -> 2762618.9 | F31: =SUM(F3:F30) -> 2080248.8 | G31: =SUM(G3:G30) -> 1987118.3 | H31: =SUM(H3:H30) -> 1766556.4 | I31: =SUM(I3:I30) -> 2460678.5 | J31: =SUM(J3:J30) -> 2304655.1 | ... N31: =SUM(N3:N30) -> 588136.68 | O31: =C31+G31+K31 -> 5933054.1 | P31: =D31+H31+L31 -> 5557027.4 | Q31: =E31+I31+M31 -> 5864286.8 | R31: =F31+J31+N31 -> 4973040.6

Sheet cumulative_ha
A1: EPPA region | B1: region name | C1: ="crop "&periods!$A$2 -> crop 2007-2010 | D1: ="crop "&periods!$A$3 -> crop 2010-2015 | E1: ="crop "&periods!$A$4 -> crop 2015-2020 | F1: ="crop "&periods!$A$5 -> crop 2020-2023 | G1: ="live "&periods!$A$2 -> live 2007-2010 | H1: ="live "&periods!$A$3 -> live 2010-2015 | I1: ="live "&periods!$A$4 -> live 2015-2020 | J1: ="live "&periods!$A$5 -> live 2020-2023 | K1: ="fors "&periods!$A$2 -> fors 2007-2010 | L1: ="fors "&periods!$A$3 -> fors 2010-2015 | M1: ="fors "&periods!$A$4 -> fors 2015-2020 | N1: ="fors "&periods!$A$5 -> fors 2020-2023 | O1: ="total "&periods!$A$2 -> total 2007-2010 | P1: ="total "&periods!$A$3 -> total 2010-2015 | Q1: ="total "&periods!$A$4 -> total 2015-2020 | R1: ="total "&periods!$A$5 -> total 2020-2023
A2: hectares, sum over the period's years
A3: USA | B3: United States of America | C3: =SUMPRODUCT((region_annual_ha!$A$2:$A$85=$A3)*(region_annual_ha!$B$2:$B$85="crop")*(region_annual_ha!$D$1:$Z$1>=periods!$B$2)*(region_annual_ha!$D$1:$Z$1<=periods!$C$2)*region_annual_ha!$D$2:$Z$85) -> 52906.766 | D3: =SUMPRODUCT((region_annual_ha!$A$2:$A$85=$A3)*(region_annual_ha!$B$2:$B$85="crop")*(region_annual_ha!$D$1:$Z$1>=periods!$B$3)*(region_annual_ha!$D$1:$Z$1<=periods!$C$3)*region_annual_ha!$D$2:$Z$85) -> 242969.58 | E3: =SUMPRODUCT((region_annual_ha!$A$2:$A$85=$A3)*(region_annual_ha!$B$2:$B$85="crop")*(region_annual_ha!$D$1:$Z$1>=periods!$B$4)*(region_annual_ha!$D$1:$Z$1<=periods!$C$4)*region_annual_ha!$D$2:$Z$85) -> 113080.47 | F3: =SUMPRODUCT((region_annual_ha!$A$2:$A$85=$A3)*(region_annual_ha!$B$2:$B$85="crop")*(region_annual_ha!$D$1:$Z$1>=periods!$B$5)*(region_annual_ha!$D$1:$Z$1<=periods!$C$5)*region_annual_ha!$D$2:$Z$85) -> 20001.503 | G3: =SUMPRODUCT((region_annual_ha!$A$2:$A$85=$A3)*(region_annual_ha!$B$2:$B$85="live")*(region_annual_ha!$D$1:$Z$1>=periods!$B$2)*(region_annual_ha!$D$1:$Z$1<=periods!$C$2)*region_annual_ha!$D$2:$Z$85) -> 226966.72 | H3: =SUMPRODUCT((region_annual_ha!$A$2:$A$85=$A3)*(region_annual_ha!$B$2:$B$85="live")*(region_annual_ha!$D$1:$Z$1>=periods!$B$3)*(region_annual_ha!$D$1:$Z$1<=periods!$C$3)*region_annual_ha!$D$2:$Z$85) -> 230184.38 | I3: =SUMPRODUCT((region_annual_ha!$A$2:$A$85=$A3)*(region_annual_ha!$B$2:$B$85="live")*(region_annual_ha!$D$1:$Z$1>=periods!$B$4)*(region_annual_ha!$D$1:$Z$1<=periods!$C$4)*region_annual_ha!$D$2:$Z$85) -> 309315.69 | J3: =SUMPRODUCT((region_annual_ha!$A$2:$A$85=$A3)*(region_annual_ha!$B$2:$B$85="live")*(region_annual_ha!$D$1:$Z$1>=periods!$B$5)*(region_annual_ha!$D$1:$Z$1<=periods!$C$5)*region_annual_ha!$D$2:$Z$85) -> 118367.75 | K3: =SUMPRODUCT((region_annual_ha!$A$2:$A$85=$A3)*(region_annual_ha!$B$2:$B$85="fors")*(region_annual_ha!$D$1:$Z$1>=periods!$B$2)*(region_annual_ha!$D$1:$Z$1<=periods!$C$2)*region_annual_ha!$D$2:$Z$85) -> 605100 | L3: =SUMPRODUCT((region_annual_ha!$A$2:$A$85=$A3)*(region_annual_ha!$B$2:$B$85="fors")*(region_annual_ha!$D$1:$Z$1>=periods!$B$3)*(region_annual_ha!$D$1:$Z$1<=periods!$C$3)*region_annual_ha!$D$2:$Z$85) -> 915800 | M3: =SUMPRODUCT((region_annual_ha!$A$2:$A$85=$A3)*(region_annual_ha!$B$2:$B$85="fors")*(region_annual_ha!$D$1:$Z$1>=periods!$B$4)*(region_annual_ha!$D$1:$Z$1<=periods!$C$4)*region_annual_ha!$D$2:$Z$85) -> 295000 | N3: =SUMPRODUCT((region_annual_ha!$A$2:$A$85=$A3)*(region_annual_ha!$B$2:$B$85="fors")*(region_annual_ha!$D$1:$Z$1>=periods!$B$5)*(region_annual_ha!$D$1:$Z$1<=periods!$C$5)*region_annual_ha!$D$2:$Z$85) -> 0 | O3: =C3+G3+K3 -> 884973.48 | P3: =D3+H3+L3 -> 1388954 | Q3: =E3+I3+M3 -> 717396.16 | R3: =F3+J3+N3 -> 138369.26
A4: CAN | B4: Canada | C4: =SUMPRODUCT((region_annual_ha!$A$2:$A$85=$A4)*(region_annual_ha!$B$2:$B$85="crop")*(region_annual_ha!$D$1:$Z$1>=periods!$B$2)*(region_annual_ha!$D$1:$Z$1<=periods!$C$2)*region_annual_ha!$D$2:$Z$85) -> 27186.278 | D4: =SUMPRODUCT((region_annual_ha!$A$2:$A$85=$A4)*(region_annual_ha!$B$2:$B$85="crop")*(region_annual_ha!$D$1:$Z$1>=periods!$B$3)*(region_annual_ha!$D$1:$Z$1<=periods!$C$3)*region_annual_ha!$D$2:$Z$85) -> 114183.52 | E4: =SUMPRODUCT((region_annual_ha!$A$2:$A$85=$A4)*(region_annual_ha!$B$2:$B$85="crop")*(region_annual_ha!$D$1:$Z$1>=periods!$B$4)*(region_annual_ha!$D$1:$Z$1<=periods!$C$4)*region_annual_ha!$D$2:$Z$85) -> 35867.37 | F4: =SUMPRODUCT((region_annual_ha!$A$2:$A$85=$A4)*(region_annual_ha!$B$2:$B$85="crop")*(region_annual_ha!$D$1:$Z$1>=periods!$B$5)*(region_annual_ha!$D$1:$Z$1<=periods!$C$5)*region_annual_ha!$D$2:$Z$85) -> 0 | G4: =SUMPRODUCT((region_annual_ha!$A$2:$A$85=$A4)*(region_annual_ha!$B$2:$B$85="live")*(region_annual_ha!$D$1:$Z$1>=periods!$B$2)*(region_annual_ha!$D$1:$Z$1<=periods!$C$2)*region_annual_ha!$D$2:$Z$85) -> 10148.028 | H4: =SUMPRODUCT((region_annual_ha!$A$2:$A$85=$A4)*(region_annual_ha!$B$2:$B$85="live")*(region_annual_ha!$D$1:$Z$1>=periods!$B$3)*(region_annual_ha!$D$1:$Z$1<=periods!$C$3)*region_annual_ha!$D$2:$Z$85) -> 0 | I4: =SUMPRODUCT((region_annual_ha!$A$2:$A$85=$A4)*(region_annual_ha!$B$2:$B$85="live")*(region_annual_ha!$D$1:$Z$1>=periods!$B$4)*(region_annual_ha!$D$1:$Z$1<=periods!$C$4)*region_annual_ha!$D$2:$Z$85) -> 31334.867 | J4: =SUMPRODUCT((region_annual_ha!$A$2:$A$85=$A4)*(region_annual_ha!$B$2:$B$85="live")*(region_annual_ha!$D$1:$Z$1>=periods!$B$5)*(region_annual_ha!$D$1:$Z$1<=periods!$C$5)*region_annual_ha!$D$2:$Z$85) -> 16251.159 | K4: =SUMPRODUCT((region_annual_ha!$A$2:$A$85=$A4)*(region_annual_ha!$B$2:$B$85="fors")*(region_annual_ha!$D$1:$Z$1>=periods!$B$2)*(region_annual_ha!$D$1:$Z$1<=periods!$C$2)*region_annual_ha!$D$2:$Z$85) -> 0 | L4: =SUMPRODUCT((region_annual_ha!$A$2:$A$85=$A4)*(region_annual_ha!$B$2:$B$85="fors")*(region_annual_ha!$D$1:$Z$1>=periods!$B$3)*(region_annual_ha!$D$1:$Z$1<=periods!$C$3)*region_annual_ha!$D$2:$Z$85) -> 0 | M4: =SUMPRODUCT((region_annual_ha!$A$2:$A$85=$A4)*(region_annual_ha!$B$2:$B$85="fors")*(region_annual_ha!$D$1:$Z$1>=periods!$B$4)*(region_annual_ha!$D$1:$Z$1<=periods!$C$4)*region_annual_ha!$D$2:$Z$85) -> 0 | N4: =SUMPRODUCT((region_annual_ha!$A$2:$A$85=$A4)*(region_annual_ha!$B$2:$B$85="fors")*(region_annual_ha!$D$1:$Z$1>=periods!$B$5)*(region_annual_ha!$D$1:$Z$1<=periods!$C$5)*region_annual_ha!$D$2:$Z$85) -> 0 | O4: =C4+G4+K4 -> 37334.306 | P4: =D4+H4+L4 -> 114183.52 | Q4: =E4+I4+M4 -> 67202.237 | R4: =F4+J4+N4 -> 16251.159
A5: MEX | B5: Mexico | C5: =SUMPRODUCT((region_annual_ha!$A$2:$A$85=$A5)*(region_annual_ha!$B$2:$B$85="crop")*(region_annual_ha!$D$1:$Z$1>=periods!$B$2)*(region_annual_ha!$D$1:$Z$1<=periods!$C$2)*region_annual_ha!$D$2:$Z$85) -> 23974.105 | D5: =SUMPRODUCT((region_annual_ha!$A$2:$A$85=$A5)*(region_annual_ha!$B$2:$B$85="crop")*(region_annual_ha!$D$1:$Z$1>=periods!$B$3)*(region_annual_ha!$D$1:$Z$1<=periods!$C$3)*region_annual_ha!$D$2:$Z$85) -> 35722.031 | E5: =SUMPRODUCT((region_annual_ha!$A$2:$A$85=$A5)*(region_annual_ha!$B$2:$B$85="crop")*(region_annual_ha!$D$1:$Z$1>=periods!$B$4)*(region_annual_ha!$D$1:$Z$1<=periods!$C$4)*region_annual_ha!$D$2:$Z$85) -> 604637.85 | F5: =SUMPRODUCT((region_annual_ha!$A$2:$A$85=$A5)*(region_annual_ha!$B$2:$B$85="crop")*(region_annual_ha!$D$1:$Z$1>=periods!$B$5)*(region_annual_ha!$D$1:$Z$1<=periods!$C$5)*region_annual_ha!$D$2:$Z$85) -> 0 | G5: =SUMPRODUCT((region_annual_ha!$A$2:$A$85=$A5)*(region_annual_ha!$B$2:$B$85="live")*(region_annual_ha!$D$1:$Z$1>=periods!$B$2)*(region_annual_ha!$D$1:$Z$1<=periods!$C$2)*region_annual_ha!$D$2:$Z$85) -> 0 | H5: =SUMPRODUCT((region_annual_ha!$A$2:$A$85=$A5)*(region_annual_ha!$B$2:$B$85="live")*(region_annual_ha!$D$1:$Z$1>=periods!$B$3)*(region_annual_ha!$D$1:$Z$1<=periods!$C$3)*region_annual_ha!$D$2:$Z$85) -> 113094.14 | I5: =SUMPRODUCT((region_annual_ha!$A$2:$A$85=$A5)*(region_annual_ha!$B$2:$B$85="live")*(region_annual_ha!$D$1:$Z$1>=periods!$B$4)*(region_annual_ha!$D$1:$Z$1<=periods!$C$4)*region_annual_ha!$D$2:$Z$85) -> 150038.86 | J5: =SUMPRODUCT((region_annual_ha!$A$2:$A$85=$A5)*(region_annual_ha!$B$2:$B$85="live")*(region_annual_ha!$D$1:$Z$1>=periods!$B$5)*(region_annual_ha!$D$1:$Z$1<=periods!$C$5)*region_annual_ha!$D$2:$Z$85) -> 131166.58 | K5: =SUMPRODUCT((region_annual_ha!$A$2:$A$85=$A5)*(region_annual_ha!$B$2:$B$85="fors")*(region_annual_ha!$D$1:$Z$1>=periods!$B$2)*(region_annual_ha!$D$1:$Z$1<=periods!$C$2)*region_annual_ha!$D$2:$Z$85) -> 7761.4109 | L5: =SUMPRODUCT((region_annual_ha!$A$2:$A$85=$A5)*(region_annual_ha!$B$2:$B$85="fors")*(region_annual_ha!$D$1:$Z$1>=periods!$B$3)*(region_annual_ha!$D$1:$Z$1<=periods!$C$3)*region_annual_ha!$D$2:$Z$85) -> 7885.1811 | M5: =SUMPRODUCT((region_annual_ha!$A$2:$A$85=$A5)*(region_annual_ha!$B$2:$B$85="fors")*(region_annual_ha!$D$1:$Z$1>=periods!$B$4)*(region_annual_ha!$D$1:$Z$1<=periods!$C$4)*region_annual_ha!$D$2:$Z$85) -> 0 | N5: =SUMPRODUCT((region_annual_ha!$A$2:$A$85=$A5)*(region_annual_ha!$B$2:$B$85="fors")*(region_annual_ha!$D$1:$Z$1>=periods!$B$5)*(region_annual_ha!$D$1:$Z$1<=periods!$C$5)*region_annual_ha!$D$2:$Z$85) -> 0 | O5: =C5+G5+K5 -> 31735.515 | P5: =D5+H5+L5 -> 156701.35 | Q5: =E5+I5+M5 -> 754676.7 | R5: =F5+J5+N5 -> 131166.58
A6: JPN | B6: Japan | C6: =SUMPRODUCT((region_annual_ha!$A$2:$A$85=$A6)*(region_annual_ha!$B$2:$B$85="crop")*(region_annual_ha!$D$1:$Z$1>=periods!$B$2)*(region_annual_ha!$D$1:$Z$1<=periods!$C$2)*region_annual_ha!$D$2:$Z$85) -> 4789.3398 | D6: =SUMPRODUCT((region_annual_ha!$A$2:$A$85=$A6)*(region_annual_ha!$B$2:$B$85="crop")*(region_annual_ha!$D$1:$Z$1>=periods!$B$3)*(region_annual_ha!$D$1:$Z$1<=periods!$C$3)*region_annual_ha!$D$2:$Z$85) -> 6113.5723 | E6: =SUMPRODUCT((region_annual_ha!$A$2:$A$85=$A6)*(region_annual_ha!$B$2:$B$85="crop")*(region_annual_ha!$D$1:$Z$1>=periods!$B$4)*(region_annual_ha!$D$1:$Z$1<=periods!$C$4)*region_annual_ha!$D$2:$Z$85) -> 3742.4077 | F6: =SUMPRODUCT((region_annual_ha!$A$2:$A$85=$A6)*(region_annual_ha!$B$2:$B$85="crop")*(region_annual_ha!$D$1:$Z$1>=periods!$B$5)*(region_annual_ha!$D$1:$Z$1<=periods!$C$5)*region_annual_ha!$D$2:$Z$85) -> 682.80445 | G6: =SUMPRODUCT((region_annual_ha!$A$2:$A$85=$A6)*(region_annual_ha!$B$2:$B$85="live")*(region_annual_ha!$D$1:$Z$1>=periods!$B$2)*(region_annual_ha!$D$1:$Z$1<=periods!$C$2)*region_annual_ha!$D$2:$Z$85) -> 359.35807 | H6: =SUMPRODUCT((region_annual_ha!$A$2:$A$85=$A6)*(region_annual_ha!$B$2:$B$85="live")*(region_annual_ha!$D$1:$Z$1>=periods!$B$3)*(region_annual_ha!$D$1:$Z$1<=periods!$C$3)*region_annual_ha!$D$2:$Z$85) -> 440.96737 | I6: =SUMPRODUCT((region_annual_ha!$A$2:$A$85=$A6)*(region_annual_ha!$B$2:$B$85="live")*(region_annual_ha!$D$1:$Z$1>=periods!$B$4)*(region_annual_ha!$D$1:$Z$1<=periods!$C$4)*region_annual_ha!$D$2:$Z$85) -> 527.11748 | J6: =SUMPRODUCT((region_annual_ha!$A$2:$A$85=$A6)*(region_annual_ha!$B$2:$B$85="live")*(region_annual_ha!$D$1:$Z$1>=periods!$B$5)*(region_annual_ha!$D$1:$Z$1<=periods!$C$5)*region_annual_ha!$D$2:$Z$85) -> 799.16558 | K6: =SUMPRODUCT((region_annual_ha!$A$2:$A$85=$A6)*(region_annual_ha!$B$2:$B$85="fors")*(region_annual_ha!$D$1:$Z$1>=periods!$B$2)*(region_annual_ha!$D$1:$Z$1<=periods!$C$2)*region_annual_ha!$D$2:$Z$85) -> 0 | L6: =SUMPRODUCT((region_annual_ha!$A$2:$A$85=$A6)*(region_annual_ha!$B$2:$B$85="fors")*(region_annual_ha!$D$1:$Z$1>=periods!$B$3)*(region_annual_ha!$D$1:$Z$1<=periods!$C$3)*region_annual_ha!$D$2:$Z$85) -> 0 | M6: =SUMPRODUCT((region_annual_ha!$A$2:$A$85=$A6)*(region_annual_ha!$B$2:$B$85="fors")*(region_annual_ha!$D$1:$Z$1>=periods!$B$4)*(region_annual_ha!$D$1:$Z$1<=periods!$C$4)*region_annual_ha!$D$2:$Z$85) -> 0 | N6: =SUMPRODUCT((region_annual_ha!$A$2:$A$85=$A6)*(region_annual_ha!$B$2:$B$85="fors")*(region_annual_ha!$D$1:$Z$1>=periods!$B$5)*(region_annual_ha!$D$1:$Z$1<=periods!$C$5)*region_annual_ha!$D$2:$Z$85) -> 0 | O6: =C6+G6+K6 -> 5148.6979 | P6: =D6+H6+L6 -> 6554.5396 | Q6: =E6+I6+M6 -> 4269.5252 | R6: =F6+J6+N6 -> 1481.97
A7: ANZ | B7: Australia and New Zealand (+ rest of Oceania and rest of the world) | C7: =SUMPRODUCT((region_annual_ha!$A$2:$A$85=$A7)*(region_annual_ha!$B$2:$B$85="crop")*(region_annual_ha!$D$1:$Z$1>=periods!$B$2)*(region_annual_ha!$D$1:$Z$1<=periods!$C$2)*region_annual_ha!$D$2:$Z$85) -> 118137.73 | D7: =SUMPRODUCT((region_annual_ha!$A$2:$A$85=$A7)*(region_annual_ha!$B$2:$B$85="crop")*(region_annual_ha!$D$1:$Z$1>=periods!$B$3)*(region_annual_ha!$D$1:$Z$1<=periods!$C$3)*region_annual_ha!$D$2:$Z$85) -> 185515.98 | E7: =SUMPRODUCT((region_annual_ha!$A$2:$A$85=$A7)*(region_annual_ha!$B$2:$B$85="crop")*(region_annual_ha!$D$1:$Z$1>=periods!$B$4)*(region_annual_ha!$D$1:$Z$1<=periods!$C$4)*region_annual_ha!$D$2:$Z$85) -> 90656.31 | F7: =SUMPRODUCT((region_annual_ha!$A$2:$A$85=$A7)*(region_annual_ha!$B$2:$B$85="crop")*(region_annual_ha!$D$1:$Z$1>=periods!$B$5)*(region_annual_ha!$D$1:$Z$1<=periods!$C$5)*region_annual_ha!$D$2:$Z$85) -> 28441.704 | G7: =SUMPRODUCT((region_annual_ha!$A$2:$A$85=$A7)*(region_annual_ha!$B$2:$B$85="live")*(region_annual_ha!$D$1:$Z$1>=periods!$B$2)*(region_annual_ha!$D$1:$Z$1<=periods!$C$2)*region_annual_ha!$D$2:$Z$85) -> 17802.488 | H7: =SUMPRODUCT((region_annual_ha!$A$2:$A$85=$A7)*(region_annual_ha!$B$2:$B$85="live")*(region_annual_ha!$D$1:$Z$1>=periods!$B$3)*(region_annual_ha!$D$1:$Z$1<=periods!$C$3)*region_annual_ha!$D$2:$Z$85) -> 40308.632 | I7: =SUMPRODUCT((region_annual_ha!$A$2:$A$85=$A7)*(region_annual_ha!$B$2:$B$85="live")*(region_annual_ha!$D$1:$Z$1>=periods!$B$4)*(region_annual_ha!$D$1:$Z$1<=periods!$C$4)*region_annual_ha!$D$2:$Z$85) -> 53822.28 | J7: =SUMPRODUCT((region_annual_ha!$A$2:$A$85=$A7)*(region_annual_ha!$B$2:$B$85="live")*(region_annual_ha!$D$1:$Z$1>=periods!$B$5)*(region_annual_ha!$D$1:$Z$1<=periods!$C$5)*region_annual_ha!$D$2:$Z$85) -> 31229.565 | K7: =SUMPRODUCT((region_annual_ha!$A$2:$A$85=$A7)*(region_annual_ha!$B$2:$B$85="fors")*(region_annual_ha!$D$1:$Z$1>=periods!$B$2)*(region_annual_ha!$D$1:$Z$1<=periods!$C$2)*region_annual_ha!$D$2:$Z$85) -> 42644.327 | L7: =SUMPRODUCT((region_annual_ha!$A$2:$A$85=$A7)*(region_annual_ha!$B$2:$B$85="fors")*(region_annual_ha!$D$1:$Z$1>=periods!$B$3)*(region_annual_ha!$D$1:$Z$1<=periods!$C$3)*region_annual_ha!$D$2:$Z$85) -> 19680.001 | M7: =SUMPRODUCT((region_annual_ha!$A$2:$A$85=$A7)*(region_annual_ha!$B$2:$B$85="fors")*(region_annual_ha!$D$1:$Z$1>=periods!$B$4)*(region_annual_ha!$D$1:$Z$1<=periods!$C$4)*region_annual_ha!$D$2:$Z$85) -> 75421.755 | N7: =SUMPRODUCT((region_annual_ha!$A$2:$A$85=$A7)*(region_annual_ha!$B$2:$B$85="fors")*(region_annual_ha!$D$1:$Z$1>=periods!$B$5)*(region_annual_ha!$D$1:$Z$1<=periods!$C$5)*region_annual_ha!$D$2:$Z$85) -> 52802.781 | O7: =C7+G7+K7 -> 178584.54 | P7: =D7+H7+L7 -> 245504.62 | Q7: =E7+I7+M7 -> 219900.35 | R7: =F7+J7+N7 -> 112474.05
